Traceback (most recent call last):
  File "/home/cheurte/.local/lib/python3.10/site-packages/pandas/core/indexes/base.py", line 3802, in get_loc
    return self._engine.get_loc(casted_key)
  File "pandas/_libs/index.pyx", line 138, in pandas._libs.index.IndexEngine.get_loc
  File "pandas/_libs/index.pyx", line 165, in pandas._libs.index.IndexEngine.get_loc
  File "pandas/_libs/hashtable_class_helper.pxi", line 5745, in pandas._libs.hashtable.PyObjectHashTable.get_item
  File "pandas/_libs/hashtable_class_helper.pxi", line 5753, in pandas._libs.hashtable.PyObjectHashTable.get_item
KeyError: 'A11'

The above exception was the direct cause of the following exception:

Traceback (most recent call last):
  File "/home/cheurte/Documents/data/train.py", line 102, in <module>
    train_fc(config)
  File "/home/cheurte/Documents/data/train.py", line 38, in train_fc
    train_loader, validate_loader, df_colors = load_data(config_colors=config)
  File "/home/cheurte/Documents/data/utils/training_manager.py", line 62, in load_data
    df_colors = preprocessing_low(df_colors, 0.07, "A11", "A14")
  File "/home/cheurte/Documents/data/utils/training_manager.py", line 31, in preprocessing_low
    lim = np.quantile(df[column], value_small_quantile)
  File "/home/cheurte/.local/lib/python3.10/site-packages/pandas/core/frame.py", line 3807, in __getitem__
    indexer = self.columns.get_loc(key)
  File "/home/cheurte/.local/lib/python3.10/site-packages/pandas/core/indexes/base.py", line 3804, in get_loc
    raise KeyError(key) from err
KeyError: 'A11'
